tests/test.in
40
o

0 S 100 NVDA 99 55
0 S 101 GOOG 56 1
0 B 102 NVDA 87 35
0 S 103 GOOG 26 41
0 B 104 NVDA 31 66
0 B 105 NVDA 92 87
0 S 106 NVDA 51 65
0 S 107 NVDA 54 62
0 B 108 NVDA 16 53
0 B 109 AAPL 5 93
0 B 110 GOOG 84 31
0 B 111 NVDA 6 26
0 S 112 AAPL 2 36
0 B 113 GOOG 22 27
0 S 114 NVDA 44 15
0 B 115 NVDA 70 94
0 B 116 AAPL 36 18
0 S 117 GOOG 54 41
0 B 118 NVDA 10 94
0 B 119 GOOG 10 4
0 S 120 NVDA 96 3
0 S 121 AAPL 57 1
0 S 122 NVDA 6 45
0 S 123 GOOG 59 10
0 S 124 GOOG 10 49
0 S 125 NVDA 6 55
0 B 126 AAPL 7 91
0 B 127 NVDA 4 73
0 B 128 GOOG 18 100
0 S 129 GOOG 98 41
0 S 130 AAPL 11 73
0 B 131 NVDA 79 34
0 B 132 NVDA 95 52
0 S 133 GOOG 47 3
0 B 134 AAPL 55 27
0 S 135 GOOG 9 92
0 B 136 NVDA 95 43
0 B 137 GOOG 87 72
0 B 138 AAPL 49 35
0 B 139 NVDA 72 44
0 B 140 NVDA 2 24
0 B 141 NVDA 43 82
0 B 142 GOOG 25 67
0 S 143 NVDA 85 93
0 B 144 AAPL 58 9
0 S 145 AAPL 1 63
0 S 146 NVDA 69 8
0 B 147 NVDA 14 1
0 S 148 GOOG 3 70
0 S 149 NVDA 15 83
0 C 100

1 B 200 AAPL 19 88
1 B 201 GOOG 52 18
1 B 202 AAPL 72 24
1 B 203 AAPL 22 85
1 B 204 AAPL 55 51
1 S 205 NVDA 33 63
1 S 206 GOOG 45 89
1 B 207 NVDA 42 23
1 S 208 GOOG 47 33
1 S 209 AAPL 56 58
1 B 210 GOOG 24 68
1 S 211 GOOG 27 88
1 B 212 NVDA 33 53
1 S 213 NVDA 2 35
1 S 214 AAPL 62 50
1 S 215 NVDA 18 12
1 B 216 AAPL 17 10
1 S 217 NVDA 24 78
1 S 218 GOOG 25 77
1 B 219 AAPL 18 43
1 S 220 NVDA 28 3
1 B 221 GOOG 48 74
1 S 222 NVDA 37 83
1 S 223 AAPL 40 92
1 S 224 NVDA 76 67
1 S 225 GOOG 40 22
1 B 226 AAPL 14 95
1 S 227 AAPL 56 35
1 B 228 AAPL 52 19
1 B 229 GOOG 99 76
1 S 230 AAPL 90 44
1 S 231 GOOG 59 99
1 B 232 AAPL 40 38
1 S 233 NVDA 85 94
1 S 234 NVDA 56 74
1 B 235 GOOG 25 17
1 B 236 GOOG 19 90
1 S 237 NVDA 37 7
1 S 238 AAPL 33 12
1 S 239 GOOG 43 98
1 B 240 NVDA 53 30
1 B 241 GOOG 70 34
1 S 242 GOOG 9 98
1 B 243 NVDA 85 15
1 B 244 GOOG 23 19
1 S 245 NVDA 42 22
1 B 246 AAPL 9 4
1 B 247 AAPL 34 98
1 B 248 GOOG 18 82
1 B 249 AAPL 69 34
1 C 200

2 S 300 AAPL 9 90
2 S 301 NVDA 17 92
2 B 302 GOOG 79 68
2 S 303 GOOG 5 100
2 S 304 NVDA 8 27
2 S 305 NVDA 47 68
2 S 306 GOOG 78 46
2 B 307 GOOG 52 68
2 B 308 NVDA 58 17
2 S 309 NVDA 44 86
2 B 310 AAPL 52 29
2 B 311 AAPL 9 96
2 B 312 AAPL 95 87
2 B 313 AAPL 48 85
2 S 314 GOOG 9 61
2 B 315 GOOG 55 73
2 S 316 NVDA 99 62
2 B 317 AAPL 39 5
2 B 318 GOOG 6 83
2 S 319 GOOG 73 26
2 S 320 AAPL 89 37
2 B 321 GOOG 14 86
2 B 322 AAPL 73 72
2 B 323 AAPL 43 60
2 S 324 AAPL 51 16
2 B 325 NVDA 73 74
2 B 326 GOOG 56 76
2 S 327 AAPL 28 5
2 B 328 AAPL 94 53
2 B 329 AAPL 16 48
2 B 330 GOOG 57 37
2 B 331 GOOG 9 92
2 S 332 GOOG 28 2
2 B 333 AAPL 22 22
2 B 334 NVDA 1 8
2 B 335 GOOG 58 27
2 S 336 AAPL 50 23
2 S 337 GOOG 76 66
2 S 338 NVDA 41 6
2 B 339 NVDA 87 10
2 S 340 NVDA 74 12
2 S 341 NVDA 81 63
2 B 342 AAPL 58 39
2 B 343 AAPL 28 63
2 S 344 AAPL 50 80
2 S 345 NVDA 12 11
2 S 346 GOOG 27 91
2 B 347 AAPL 77 61
2 S 348 NVDA 65 84
2 S 349 NVDA 87 23
2 C 300

3 B 400 AAPL 61 46
3 B 401 NVDA 45 88
3 S 402 GOOG 42 93
3 B 403 NVDA 52 68
3 B 404 NVDA 31 65
3 B 405 NVDA 16 98
3 S 406 AAPL 95 50
3 S 407 NVDA 55 42
3 B 408 AAPL 90 28
3 S 409 AAPL 93 82
3 S 410 AAPL 49 8
3 B 411 AAPL 60 100
3 B 412 NVDA 9 4
3 B 413 GOOG 65 27
3 B 414 AAPL 22 50
3 B 415 NVDA 75 29
3 B 416 NVDA 96 81
3 B 417 AAPL 37 66
3 S 418 AAPL 24 55
3 B 419 NVDA 27 93
3 S 420 GOOG 25 16
3 B 421 AAPL 44 66
3 B 422 AAPL 95 59
3 S 423 GOOG 73 35
3 S 424 AAPL 65 30
3 S 425 AAPL 40 44
3 B 426 NVDA 35 87
3 S 427 GOOG 57 21
3 B 428 NVDA 52 74
3 S 429 GOOG 29 10
3 B 430 AAPL 19 94
3 B 431 AAPL 69 14
3 S 432 AAPL 85 13
3 B 433 GOOG 17 95
3 B 434 GOOG 70 5
3 B 435 NVDA 46 100
3 S 436 AAPL 85 72
3 S 437 GOOG 38 38
3 S 438 GOOG 24 2
3 B 439 AAPL 84 86
3 B 440 NVDA 16 19
3 S 441 NVDA 42 6
3 B 442 NVDA 5 72
3 B 443 AAPL 76 94
3 B 444 GOOG 79 37
3 S 445 GOOG 68 10
3 S 446 NVDA 2 59
3 S 447 NVDA 79 84
3 S 448 GOOG 9 35
3 S 449 AAPL 65 11
3 C 400

4 S 500 NVDA 2 2
4 S 501 NVDA 46 53
4 B 502 GOOG 50 82
4 B 503 AAPL 87 22
4 B 504 GOOG 81 71
4 S 505 GOOG 54 76
4 S 506 AAPL 9 37
4 S 507 NVDA 94 89
4 B 508 NVDA 39 48
4 B 509 GOOG 50 94
4 S 510 NVDA 97 76
4 S 511 AAPL 66 25
4 B 512 NVDA 21 41
4 B 513 NVDA 81 70
4 S 514 GOOG 79 36
4 B 515 NVDA 88 40
4 B 516 GOOG 31 76
4 S 517 AAPL 55 36
4 B 518 NVDA 90 81
4 S 519 AAPL 87 44
4 B 520 NVDA 68 70
4 B 521 GOOG 88 7
4 S 522 AAPL 92 37
4 B 523 NVDA 15 5
4 S 524 AAPL 34 80
4 S 525 NVDA 12 45
4 S 526 NVDA 48 83
4 S 527 NVDA 57 75
4 S 528 NVDA 2 83
4 B 529 GOOG 97 18
4 S 530 NVDA 67 43
4 S 531 NVDA 56 54
4 B 532 GOOG 38 43
4 S 533 NVDA 44 72
4 S 534 NVDA 76 43
4 B 535 NVDA 37 26
4 S 536 AAPL 32 57
4 S 537 NVDA 26 8
4 B 538 AAPL 28 47
4 S 539 GOOG 17 61
4 S 540 AAPL 97 12
4 S 541 NVDA 59 49
4 B 542 NVDA 57 42
4 S 543 NVDA 28 49
4 B 544 GOOG 76 100
4 B 545 AAPL 3 18
4 S 546 AAPL 35 36
4 S 547 NVDA 74 10
4 B 548 AAPL 95 50
4 B 549 AAPL 18 97
4 C 500

5 S 600 AAPL 43 54
5 S 601 NVDA 61 11
5 B 602 NVDA 78 34
5 S 603 AAPL 27 8
5 S 604 AAPL 20 13
5 S 605 GOOG 6 1
5 B 606 AAPL 76 31
5 S 607 GOOG 35 93
5 S 608 AAPL 18 36
5 S 609 NVDA 92 61
5 B 610 GOOG 30 50
5 B 611 AAPL 63 7
5 B 612 AAPL 84 42
5 S 613 GOOG 50 76
5 S 614 GOOG 39 12
5 B 615 AAPL 54 58
5 S 616 AAPL 2 58
5 S 617 NVDA 14 78
5 B 618 GOOG 30 39
5 S 619 AAPL 94 56
5 B 620 NVDA 94 38
5 B 621 GOOG 62 89
5 S 622 AAPL 80 12
5 B 623 AAPL 70 63
5 B 624 NVDA 92 97
5 B 625 NVDA 34 21
5 B 626 GOOG 45 91
5 S 627 GOOG 77 13
5 B 628 NVDA 76 67
5 S 629 GOOG 93 2
5 B 630 AAPL 73 20
5 B 631 NVDA 43 87
5 B 632 AAPL 75 84
5 S 633 NVDA 25 76
5 B 634 GOOG 86 49
5 B 635 NVDA 56 25
5 B 636 AAPL 92 7
5 S 637 NVDA 90 21
5 B 638 AAPL 1 49
5 S 639 AAPL 37 36
5 B 640 AAPL 98 97
5 B 641 GOOG 31 22
5 B 642 NVDA 44 77
5 B 643 GOOG 80 34
5 S 644 AAPL 80 13
5 S 645 AAPL 84 59
5 B 646 NVDA 56 17
5 S 647 GOOG 17 90
5 B 648 NVDA 85 54
5 S 649 AAPL 4 13
5 C 600

6 B 700 AAPL 86 37
6 B 701 GOOG 64 63
6 S 702 AAPL 37 84
6 B 703 NVDA 60 39
6 S 704 AAPL 16 18
6 S 705 NVDA 53 6
6 S 706 NVDA 85 9
6 B 707 AAPL 43 94
6 S 708 AAPL 86 89
6 S 709 AAPL 36 17
6 B 710 GOOG 25 80
6 B 711 NVDA 48 92
6 S 712 NVDA 63 33
6 B 713 AAPL 41 32
6 S 714 NVDA 89 61
6 S 715 GOOG 32 95
6 S 716 AAPL 62 77
6 S 717 GOOG 64 16
6 B 718 GOOG 46 28
6 S 719 GOOG 20 30
6 S 720 GOOG 31 2
6 B 721 AAPL 78 42
6 B 722 GOOG 43 7
6 B 723 GOOG 31 13
6 S 724 GOOG 12 41
6 S 725 GOOG 29 60
6 S 726 GOOG 23 26
6 B 727 NVDA 91 78
6 S 728 GOOG 2 80
6 B 729 GOOG 50 25
6 S 730 NVDA 80 79
6 S 731 GOOG 9 63
6 S 732 AAPL 18 77
6 B 733 NVDA 91 77
6 B 734 NVDA 73 44
6 B 735 NVDA 14 75
6 S 736 NVDA 25 38
6 B 737 GOOG 32 84
6 S 738 AAPL 44 45
6 B 739 NVDA 21 27
6 B 740 NVDA 11 45
6 S 741 NVDA 57 42
6 B 742 GOOG 24 94
6 S 743 GOOG 6 26
6 S 744 GOOG 37 84
6 S 745 AAPL 34 23
6 S 746 GOOG 94 37
6 S 747 NVDA 4 8
6 S 748 AAPL 29 78
6 B 749 AAPL 17 34
6 C 700

7 B 800 GOOG 3 58
7 S 801 GOOG 52 31
7 B 802 NVDA 10 20
7 S 803 AAPL 56 8
7 B 804 GOOG 75 21
7 B 805 NVDA 27 23
7 B 806 NVDA 18 98
7 B 807 AAPL 99 1
7 B 808 NVDA 29 76
7 B 809 AAPL 64 51
7 B 810 AAPL 58 75
7 B 811 NVDA 28 61
7 B 812 GOOG 66 51
7 B 813 NVDA 11 70
7 B 814 AAPL 26 7
7 S 815 NVDA 67 56
7 S 816 NVDA 65 72
7 B 817 AAPL 58 3
7 B 818 AAPL 45 87
7 B 819 NVDA 89 34
7 S 820 NVDA 87 43
7 S 821 AAPL 60 50
7 S 822 NVDA 52 82
7 S 823 NVDA 14 56
7 B 824 NVDA 25 93
7 B 825 NVDA 1 53
7 B 826 NVDA 36 94
7 S 827 NVDA 69 8
7 S 828 NVDA 34 67
7 B 829 AAPL 86 39
7 B 830 AAPL 35 43
7 B 831 NVDA 53 44
7 B 832 GOOG 98 43
7 B 833 GOOG 63 68
7 S 834 GOOG 80 27
7 B 835 NVDA 85 30
7 B 836 NVDA 69 81
7 B 837 GOOG 57 11
7 B 838 NVDA 37 10
7 B 839 GOOG 53 94
7 B 840 GOOG 53 96
7 S 841 AAPL 23 98
7 S 842 GOOG 96 33
7 S 843 NVDA 15 60
7 B 844 GOOG 41 27
7 S 845 AAPL 25 34
7 S 846 GOOG 58 88
7 S 847 GOOG 68 92
7 B 848 NVDA 47 40
7 B 849 NVDA 34 35
7 C 800

8 S 900 GOOG 94 68
8 B 901 AAPL 42 56
8 B 902 GOOG 95 37
8 B 903 GOOG 86 51
8 S 904 AAPL 17 76
8 S 905 AAPL 73 33
8 B 906 AAPL 10 100
8 B 907 GOOG 6 10
8 S 908 NVDA 14 52
8 S 909 AAPL 93 68
8 B 910 AAPL 24 25
8 B 911 AAPL 87 21
8 B 912 AAPL 37 91
8 S 913 AAPL 55 1
8 B 914 AAPL 52 99
8 B 915 GOOG 91 46
8 S 916 AAPL 24 40
8 S 917 GOOG 100 88
8 B 918 GOOG 34 90
8 S 919 GOOG 4 3
8 S 920 NVDA 52 42
8 S 921 NVDA 90 32
