tests/two-threads.in
5

o

0 B 100 AAPL 1000 100
0 B 101 AAPL 1000 50
0 S 102 AAPL 500 50
0 S 103 AAPL 500 10
0 S 104 AAPL 100 10
0 C 104


1 S 200 AAPL 1000 120
1 S 201 AAPL 1000 10
1 B 202 AAPL 1000 10
1 B 203 AAPL 1000 10
1 C 200
1 B 204 AAPL 1000 20
1 B 205 AAPL 1000 30

2 S 300 GOOG 100 100 
2 S 301 AAPL 100 100
2 B 302 GOOG 100 100
2 S 303 GOOG 100 100

3 B 400 GOOG 200 1
3 C 400 
3 B 401 GOOG 200 1

4 B 500 GOOG 100 1
4 B 501 GOOG 1000 1
4 C 501
4 S 502 GOOG 100 1
4 S 503 AAPL 100 10
4 B 504 GOOG 100 1

x
